Workbook

Sheet Instrucciones
A1: Cotización: Junta cementosa de alto desempeño
A2: Producto: Laticrete PermaColor Select / Mapei Ultracolor Plus FA
A4: Cómo usar este archivo
A5: 1. Ve a la hoja «Costos» y cambia las celdas AZULES con fondo AMARILLO por tus datos reales: pago por hora, cantidades y precios de material, hospedaje y margen de ganancia.
A6: 2. Todo lo demás se recalcula solo: costo total, precio de venta, ganancia y margen.
A7: 3. La hoja «Quote (cliente)» ya está en inglés y toma los números de «Costos» (texto verde = vínculo a otra hoja). Llena nombre, fecha y tus datos, y borra la fila de control interno antes de enviarla.
A8: 4. El precio se calcula como Costo total ÷ (1 − margen), para que el margen que pidas sea el que realmente ganes.
A10: Datos que usé
A11: • 530 ft², 2 personas, 2 días en total (día 1: quitar junta y rejuntar; día 2: lavado a mano y sellado).
A12: • Sellador J26WB a $400 por cubeta (dato tuyo). Puse 1 cubeta: confirma en la ficha técnica que alcanza para 530 ft² en 2 manos.
A13: • Los demás precios son ESTIMACIONES de tiendas en EE. UU.; están marcados en la columna de notas. Verifícalos con tu proveedor.
A15: Sobre esta opción de junta
... A22: • Juntas de expansión: en bordes, muros y cada 8–12 ft en exterior, usa sellador flexible de poliuretano, no junta rígida.

Sheet Costos
A1: Costos y ganancia — Junta cementosa de alto desempeño
A2: Producto: Laticrete PermaColor Select / Mapei Ultracolor Plus FA · Piso de piedra 530 ft² · Yellowstone Club, Big Sky, MT
A3: Celdas en azul con fondo amarillo = datos que puedes cambiar. Todo lo demás se calcula solo.
A5: DATOS GENERALES
A6: Concepto | B6: Valor | C6: Unidad | F6: Nota
A7: Área del piso | B7: 530 | C7: ft² | F7: Dato del usuario.
A8: Personas trabajando | B8: 2 | C8: personas | F8: Dato del usuario.
A9: Horas por día | B9: 9 | C9: horas | F9: Estimación: ajusta a tu jornada real.
A10: Pago por hora por persona | B10: 35 | C10: USD/hora | F10: Estimación: pon lo que pagas a tus trabajadores (o lo que vale tu hora).
A11: Contingencia (imprevistos) | B11: 0.1 | C11: % del costo | F11: Recomendado 10 %: piezas flojas, juntas más profundas, etc.
A12: Margen de ganancia deseado | B12: 0.35 | C12: % del precio | F12: 20–35 % normal; 35–50 % en trabajos de lujo o remotos.
A14: MANO DE OBRA (2 días en total, 2 personas)
A15: Tarea | B15: Días | C15: Unidad | D15: Costo por día | E15: Total | F15: Nota
A16: Quitar junta vieja y rejuntar | B16: 1 | C16: días | D16: =$B$8*$B$9*$B$10 | E16: =B16*D16 | F16: Día 1.
A17: Lavado profundo a mano | B17: 0.5 | C17: días | D17: =$B$8*$B$9*$B$10 | E17: =B17*D17 | F17: Día 2 (mañana). Lavado 100 % a mano, sin máquina.
A18: Sellado con J26WB (2 manos) | B18: 0.5 | C18: días | D18: =$B$8*$B$9*$B$10 | E18: =B18*D18 | F18: Día 2 (tarde). Revisa en la ficha de la junta cuánto tiempo debe curar antes de sellar.
A19: Subtotal mano de obra | B19: =SUM(B16:B18) | C19: días | E19: =SUM(E16:E18)
A21: MATERIALES (a precio de tienda)
A22: Material | B22: Cantidad | C22: Unidad | D22: Precio unitario | E22: Total | F22: Nota / fuente
A23: Junta cementosa alto desempeño (PermaColor Select / Ultracolor Plus FA) | B23: 6 | C23: bolsa 25 lb | D23: 45 | E23: =B23*D23 | F23: Estimación: $35–$55 por bolsa; 4–8 bolsas. PermaColor Select se vende aparte del kit de color.
A24: Esponjas, llana de hule, cubetas | B24: 1 | C24: kit | D24: 60 | E24: =B24*D24 | F24: Estimación.
A25: Sellador J26WB | B25: 1 | C25: cubeta | D25: 400 | E25: =B25*D25 | F25: Precio dado por el usuario: $400 por cubeta. Verifica en la ficha técnica cuántos ft² cubre una cubeta en 2 manos; si no alcanza para 530 ft², sube la cantidad.
A26: Sellador flexible de poliuretano (juntas de expansión) | B26: 9 | C26: cartucho 10 oz | D26: 12 | E26: =B26*D26 | F26: Estimación: $8–$15 por cartucho. Para bordes, muros y juntas cada 8–12 ft.
A27: Cordón de respaldo (backer rod) | B27: 1 | C27: rollo | D27: 18 | E27: =B27*D27 | F27: Estimación: $10–$25.
A28: Limpiador pH neutro para piedra + cepillos y fibras (lavado a mano) | B28: 1 | C28: kit | D28: 150 | E28: =B28*D28 | F28: Estimación. Lavado 100 % a mano.
A29: Discos/herramienta para quitar junta, cinta, plástico de protección | B29: 1 | C29: kit | D29: 200 | E29: =B29*D29 | F29: Estimación.
A30: Subtotal materiales | E30: =SUM(E23:E29)
A32: OTROS COSTOS
A33: Concepto | B33: Cantidad | C33: Unidad | D33: Precio unitario | E33: Total | F33: Nota
A34: Gasolina, traslado y comidas | B34: 1 | C34: viaje | D34: 400 | E34: =B34*D34 | F34: Estimación para 2 días.
A35: Hospedaje | B35: 2 | C35: noches | D35: 200 | E35: =B35*D35 | F35: Estimación. Si vives cerca de Big Sky, pon 0 noches.
A36: Seguro / registro de contratista en el club | B36: 1 | C36: pago | D36: 400 | E36: =B36*D36 | F36: Estimación. El club suele pedir certificado de seguro (COI).
A37: Disposición de residuos | B37: 1 | C37: pago | D37: 100 | E37: =B37*D37 | F37: Estimación.
A38: Subtotal otros costos | E38: =SUM(E34:E37)
A40: RESUMEN: COSTO, PRECIO Y GANANCIA
A41: Costo directo (mano de obra + materiales + otros) | E41: =E19+E30+E38
A42: Contingencia | E42: =E41*$B$11
A43: COSTO TOTAL (lo que te cuesta a ti) | E43: =E41+E42
A44: PRECIO DE VENTA (lo que cobras) | E44: =E43/(1-$B$12) | F44: Precio = Costo total ÷ (1 − margen). Así el margen sale exacto.
A45: GANANCIA | E45: =E44-E43
...

Sheet Quote (cliente)
A1: ESTIMATE — Stone Floor Restoration
A3: Client: ______________________________
A4: Location: Yellowstone Club, Big Sky, MT
A5: Date: ______________ Valid for: 30 days
A6: ='Costos'!B7
A8: Scope of work
A9: 1. Protect surrounding surfaces, walls, and fixtures.
A10: 2. Remove existing grout from all joints.
A11: 3. Re-grout all joints with high-performance, freeze-thaw rated cementitious grout (Laticrete PermaColor Select or equivalent).
A12: 4. Hand-scrub deep cleaning of the entire stone surface using a pH-neutral, stone-safe cleaner and soft brushes (no machines), including haze removal, rinsing, and drying.
A13: 5. Apply J26WB sealer (2 coats) per manufacturer specifications.
A14: 6. Install flexible polyurethane sealant at perimeter and movement joints.
A15: 7. Final cleanup and disposal of debris.
A17: Item | B17: Amount (USD)
A18: Grout removal & re-grouting (labor) | B18: ='Costos'!E16*(1+'Costos'!$B$11)/(1-'Costos'!$B$12)
A19: Hand-scrub deep cleaning (labor) | B19: ='Costos'!E17*(1+'Costos'!$B$11)/(1-'Costos'!$B$12)
A20: Sealing – 2 coats (labor) | B20: ='Costos'!E18*(1+'Costos'!$B$11)/(1-'Costos'!$B$12)
A21: Materials (high-performance cementitious grout (Laticrete PermaColor Select or equivalent), J26WB sealer, sealant, supplies) | B21: ='Costos'!E30*(1+'Costos'!$B$11)/(1-'Costos'!$B$12)
A22: Mobilization, travel & site requirements | B22: ='Costos'!E38*(1+'Costos'!$B$11)/(1-'Costos'!$B$12)
A23: TOTAL | B23: =SUM(B18:B22)
A25: Terms & notes
A26: • Estimated duration: 2 working days (plus cure time required by the grout and sealer manufacturers).
A27: • Payment terms: 50% deposit to schedule, balance upon completion.
A28: • Price assumes stone is in sound condition. Repair or replacement of loose or damaged stones, if needed, will be quoted separately.
A29: • Foot traffic should be limited for 24–72 hours after sealing.
A31: Contractor: ______________________ Phone / Email: ______________________
A33: Control interno (borra esta fila antes de enviar): el total debe ser igual al PRECIO DE VENTA de la hoja Costos → | B33: =B23-'Costos'!E44
